sample3_1000_out.txt
33209300 S 44059.00 
33215565 S NA 
33215753 S 44060.00 
33232547 S NA 
33809789 S 43855.43 
33809810 S 44036.79 
33809811 S 43857.43 
33814163 S NA 
33907506 S 43986.20 
33907751 S NA 
33928720 B 44233.00 
33928729 B NA 
33928736 B 44233.00 
33936379 B NA 
33963683 S 44067.70 
33963684 S 43976.20 
33963684 S 44068.70 
33973111 S 43976.20 
33973112 S 44069.70 
34040170 S 43635.80 
34040171 S NA 
34040172 S 43634.80 
34048008 S NA 
34048008 S 43635.80 
34048038 S 43815.40 
34048049 S 43983.60 
34048049 S 43815.40 
34050455 S NA 
34062173 S 43970.20 
34062173 S 43749.40 
34062174 S 43970.20 
34062598 S 43957.40 
34062605 S 43971.50 
34095516 S NA 
34106448 S 43962.50 
34120932 S NA 
34162888 S 43830.10 
34162928 S 43986.90 
34162928 S 43830.10 
34167639 S 43986.90 
34167640 S 43830.10 
34168117 S NA 
34168117 S 43549.10 
34175314 S NA 
34179829 S 43549.10 
34179830 S 44042.60 
34181418 S 44076.20 
34181418 S 44042.60 
34181449 S 44077.20 
34181449 S 44043.60 
34181480 S 44078.20 
34181481 S 44043.60 
34181512 S 44079.20 
34181512 S 44044.60 
34181543 S 44080.20 
34181543 S 44044.60 
34184108 S 43993.90 
34184108 S 44043.10 
34184109 B 44291.50 
34184111 S 44093.50 
34184112 S 44091.50 
34184112 B 44210.50 
34184112 S 44094.00 
34184113 S 44045.60 
34184113 S 44096.00 
34184118 S 44045.60 
34184118 S 44094.00 
34184120 S 44043.60 
34184138 B 44190.00 
34184138 B 44207.50 
34184148 S 43947.90 
34184169 B 44187.00 
34184169 B 44207.50 
34184195 S 44042.60 
34184237 S 43947.90 
34184267 S 44041.60 
34184287 B 44228.50 
34184298 S 44076.20 
34184298 S 44042.60 
34184317 B 44207.50 
34184397 S 43992.90 
34184397 S 44043.60 
34184398 B 44288.50 
34184398 B 44207.50 
34184399 B 44288.50 
34184427 B NA 
34184457 B 44290.50 
34184487 B NA 
34184516 B 44290.50 
34184618 B 44242.50 
34184618 B 44290.50 
34188328 S 44086.20 
34188328 B 44235.50 
34188329 B NA 
34188367 S 44090.60 
34188368 S 44086.20 
34188368 B 44297.50 
34188368 B NA 
34188399 S 44090.60 
34188399 S 44086.20 
34188430 S 44090.60 
34188430 S 44086.20 
34188461 S 44090.60 
34188461 S 44086.20 
34189440 S 44076.70 
34189440 S 43992.90 
34189442 B 44287.50 
34189443 B 44206.50 
34189465 B 44232.50 
34189465 S 44073.70 
34189465 B 44205.50 
34189466 B 44231.50 
34189466 B 44204.50 
34189474 B 44231.50 
34189475 B 44204.50 
34189476 B 44231.50 
34189476 B 44204.50 
34189477 B 44231.50 
34189477 B 44204.50 
34189478 B 44231.50 
34189478 B 44205.50 
34189480 S 44083.60 
34189481 S 44073.70 
34189481 B 44187.00 
34189481 B 44205.50 
34189490 S 43997.90 
34189522 B 44187.00 
34189523 B 44205.50 
34189523 S 44074.70 
34189553 B 44187.00 
34189554 B 44205.50 
34190793 B 44234.50 
34190794 B 44290.50 
34190794 S 44089.50 
34190794 B 44235.50 
34190795 S 44074.70 
34190795 B 44290.50 
34190795 S 44092.50 
34190795 B 44234.50 
34190796 B NA 
34190801 B 44239.50 
34190808 B 44294.50 
34190808 B 44239.50 
34190809 B 44190.00 
34190843 S 44074.70 
34190843 S 43990.90 
34190848 B 44215.50 
34190848 S 44071.70 
34190848 B 44189.00 
34190849 S 43990.90 
34190849 S 44072.70 
34190849 B 44214.50 
34190850 B 44188.00 
34190850 S 43991.90 
34190850 B 44237.50 
34190851 B 44186.00 
34190851 S 44073.70 
34190851 S 43991.90 
34190852 S 44073.70 
34190852 S 43991.90 
34190852 S 44073.70 
34190853 S 43991.90 
34190853 S 44073.70 
34190854 S 43991.90 
34190854 S 44073.70 
34190855 S 43991.90 
34190855 S 44073.70 
34190856 S 43991.90 
34190856 S 44073.70 
34190857 S 43991.90 
34190857 S 44073.70 
34190857 B 44237.50 
34190857 B 44186.00 
34190858 S 43991.90 
34190858 B 44212.50 
34190858 S 44074.70 
34190858 B 44186.00 
34190858 B 44237.50 
34190859 B 44186.00 
34190859 S 43992.90 
34190859 B 44212.50 
34190859 S 44075.70 
34190859 B 44186.00 
34190860 S 43992.90 
34190860 S 44075.70 
34190861 S 43992.90 
34190861 S 44075.70 
34190867 B 44212.50 
34190867 B 44186.00 
34190868 S 43992.90 
34190868 S 44075.70 
34190869 B 44212.50 
34190869 B 44186.00 
34190869 S 43992.90 
34190869 S 44069.70 
34190869 S 44086.50 
34190870 S 44075.70 
34190870 S 43992.90 
34190870 S 44075.70 
34190871 B 44212.50 
34190871 B 44187.00 
34190872 S 43992.90 
34190872 S 44075.70 
34190873 S 43992.90 
34190873 S 44076.70 
34190879 B 44234.50 
34190888 B 44214.50 
34190888 B 44233.50 
34190889 S 43999.90 
34190897 S 43835.10 
34190897 S 43997.90 
34190918 B 44282.50 
34190928 S 44073.70 
34190929 S 44083.60 
34190930 S 44073.70 
34190948 B 44233.50 
34190949 B 44213.50 
34190950 B 44233.50 
34191047 B 44213.50 
34191048 B 44233.50 
34194398 S 44083.60 
34194398 S 44073.70 
34194454 S 44084.60 
34194455 S 44074.70 
34194636 S 44099.10 
34194637 S 44095.50 
34194637 B NA 
34194638 S 44102.10 
34194639 S 44095.50 
34194639 S 44102.10 
34195788 S 44095.50 
34195789 S 44102.10 
34195805 S 44095.50 
34195805 S 44102.10 
34195806 B 44297.50 
34195806 B 44243.50 
34195806 S 44105.10 
34195806 S 44102.10 
34195806 S 44095.50 
34195807 S 44103.10 
34195808 B 44216.50 
34195817 B 44236.50 
34195818 B 44290.50 
34195819 B 44235.50 
34195819 S 44096.50 
34195819 S 44100.10 
34195819 S 44092.50 
34195819 S 44099.10 
34195820 B 44290.50 
34195820 B 44234.50 
34195822 B 44290.50 
34195846 B 44242.50 
34195848 B 44222.50 
34195848 B 44241.50 
34195849 B 44290.50 
34195905 B 44242.50 
34198158 B 44290.50 
34198188 B 44242.50 
34198278 B 44153.00 
34199851 S 44092.50 
34199852 S 44100.10 
34199859 B 44161.00 
34199859 B 44154.00 
34199966 B 44163.60 
34199969 S 44102.10 
34199988 B 44171.80 
34199988 B 44193.20 
34199988 B 44172.80 
34199988 B 44164.60 
34199989 S 44104.10 
34199998 B 44171.80 
34199998 B 44163.60 
34199999 B 44171.80 
34199999 B 44164.60 
34200004 B 44156.60 
34200007 B 44162.60 
34200008 B 44155.60 
34200010 B 44162.60 
34200011 B 44156.60 
34200013 S 44108.10 
34200014 S 44104.10 
34200014 S 44108.10 
34200023 S 44106.10 
34200032 S 44102.10 
34200042 S 44095.40 
34200043 S 44102.10 
34200044 B 44162.60 
34200044 B 44155.60 
34200046 S 44106.10 
34200049 B 44162.60 
34200049 S 44108.10 
34200050 B 44155.60 
34200050 S 44104.10 
34200050 S 44102.10 
34200051 S 44104.10 
34200051 S 44100.10 
34200051 S 44095.40 
34200052 B 44162.60 
34200052 S 44102.10 
34200052 B 44154.60 
34200053 S 44095.40 
34200053 S 44100.10 
34200054 B 44162.60 
34200055 B 44154.60 
34200075 B 44161.60 
34200075 B 44154.60 
34200076 S 44083.70 
34200076 S 44100.10 
34200230 B 44162.60 
34200230 B 44171.80 
34200231 S 44094.50 
34200231 S 44100.10 
34200231 B 44162.60 
34200232 S 44094.50 
34200232 S 44100.10 
34200232 S 44094.50 
34200232 S 44102.10 
34200233 B 44170.80 
34200234 B 44162.60 
34200238 B 44242.50 
34200249 B 44297.50 
34200249 B 44243.50 
34200265 B 44299.50 
34200269 B 44246.50 
34200271 B 44299.50 
34200272 B 44222.50 
34200272 B 44295.50 
34200273 B 44218.50 
34200300 B 44237.50 
34200317 S 44096.50 
34200318 S 44104.10 
34200331 B 44218.50 
34200350 B 44237.50 
34200381 B 44218.50 
34200449 S 44086.70 
34200449 S 44112.10 
34200453 B 44295.50 
34200454 B 44243.50 
34200455 B 44295.50 
34200480 B 45378.62 
34200509 B NA 
34200509 B 45379.62 
34200509 B 44297.50 
34200514 B 44245.50 
34200518 B 44298.50 
34200519 B 44244.50 
34200522 S 44114.10 
34200523 B 44298.50 
34200524 B 44245.50 
34200543 S 44118.10 
34200544 S 44114.10 
34200544 S 44110.10 
34200544 S 44114.10 
34200544 S 44118.10 
34200545 S 44110.10 
34200545 S 44118.10 
34200546 S 44114.10 
34200546 S 44110.10 
34200546 S 44103.40 
34200546 S 44110.10 
34200546 S 44114.10 
34200548 B 44292.50 
34200579 B 44245.50 
34200588 S 44104.30 
34200588 S 44114.10 
34200601 S 44118.10 
34200602 S 44114.10 
34200602 S 44110.10 
34200602 S 44114.10 
34200603 S 44118.10 
34200609 S 44114.10 
34200673 S 44119.10 
34200674 S 44115.10 
34200674 S 44120.10 
34200674 S 44116.10 
34200675 S 44121.10 
34200677 S 44125.10 
34200677 S 44121.10 
34200680 S 44126.10 
34200682 S 44121.10 
34200683 S 44126.10 
34200722 S 44121.10 
34200723 S 44116.10 
34200837 S 44114.10 
34200839 S 44107.30 
34200839 S 44113.10 
34200861 B 44221.50 
