test_out.txt
28800758 S 11037.56 
28800796 S NA
28800812 S 11037.56 
28812071 S NA
28814087 B 11045.00 
28815937 B NA
28816245 B 11053.50 
28816245 B NA
28817570 B 11038.20 
28822172 B NA
28823984 S 10991.00 
28823984 S NA
28835564 S 10941.00 
28835565 S NA
28838797 B 11037.50 
28845097 B 11025.00 
28855165 S 10960.00 
28855165 S NA
28869845 S 10967.00 
28874354 S NA
28874384 S 10954.00 
28876376 S NA
28876679 S 10962.50 
28887878 S NA
28890455 S 10930.00 
28890455 S NA
28893420 B 11019.00 
28893682 S 10943.00 
28900102 B 11025.00 
28900102 S 11010.00 
28901422 S 10960.00 
28902514 B 11020.00 
28902534 S NA
28902571 S 10949.00 
28903189 S 10967.50 
28903190 B 11015.00 
28903191 S 10949.00 
28903191 B 11020.00 
28903215 S 10967.50 
28903217 B 11015.00 
28903224 S 10970.50 
28903234 S 10962.00 
28903281 S 10970.50 
28903874 B 11020.00 
28904189 S 10955.00 
28904189 B 11025.00 
28904224 S NA
28904253 S 10949.00 
28906024 S 10960.50 
28906024 S 10955.00 
28910721 B 11020.14 
28910722 B 11025.00 
28910723 B 11020.14 
28910744 B 11015.14 
28910934 S 10963.50 
28910934 S 10955.00 
28911618 B 11017.21 
28912943 B 11026.00 
28912944 B 11012.35 
28917479 B 11026.00 
28917481 S 10971.50 
28917481 B 11015.50 
28917483 S 10955.00 
28917483 B 11026.00 
28917524 S 10964.50 
28917525 S 10956.00 
28917525 S NA
28917531 S 10963.00 
28917539 B 11015.50 
28917581 S 10972.00 
28918102 S 10978.00 
28918103 B 11026.00 
28918132 B 11015.50 
28918662 S 10971.00 
28918687 S 10977.00 
28919173 S 10970.50 
28919173 B 11026.00 
28919173 B 11013.10 
28919248 S 10976.00 
28919260 B 11005.18 
28919822 B 11014.50 
28919823 B 11005.18 
28922492 S 10970.50 
28922492 B 11013.10 
28923035 B 11026.00 
28923083 B 11037.00 
28923113 B 11032.00 
28923389 S 10975.20 
28923389 B 11023.21 
28923390 S 10970.50 
28923390 B 11032.00 
28923391 S 10975.20 
28923391 B 11023.21 
28923830 S 10981.60 
28923831 S 10975.20 
28923832 S 10981.60 
28924704 S 10978.00 
28924704 B 11032.00 
28924704 S 10970.50 
28924705 B 11023.21 
28924706 S 10975.20 
28924706 S 10981.60 
28925782 B 11032.00 
28925782 S 10975.20 
28925782 S 10970.50 
28925783 B 11023.21 
28925784 S 10975.20 
28925784 S 10981.60 
28927133 B 11032.00 
28927133 S 10978.00 
28927134 B 11023.21 
28927135 S 10981.60 
28928212 S 10978.00 
28928212 B 11032.00 
28928213 S 10981.60 
28928213 B 11023.21 
28929118 B 11032.00 
28929120 S 10982.50 
28929120 B 11021.50 
28929121 S 10981.60 
28929121 S 10975.20 
28929121 B 11032.00 
28929122 S 10970.50 
28929122 S 10978.00 
28929123 B 11028.59 
28929123 S 10981.60 
28929128 B 11019.02 
28929146 S 10982.50 
28929155 B 11018.64 
28929156 B 11019.02 
28929164 B 11021.59 
28929214 B 11019.02 
28929949 B 11028.59 
28929949 S 10981.60 
28929980 S 10978.00 
28929981 B 11032.00 
28929984 B 11037.00 
28930015 B 11032.00 
28933055 S 10985.00 
28933058 S 10986.00 
28933092 S 10985.00 
28933093 S 10986.00 
28937566 B 11026.00 
28937567 S 10985.00 
28937568 S 10988.00 
28937974 S 10985.00 
28937976 S 10988.00 
28938015 S 10985.00 
28938016 S 10988.00 
28939185 S 10985.00 
28939187 S 10988.00 
28941591 S 10985.00 
28941592 S 10989.00 
28952850 S 10985.00 
28953184 B 11018.00 
28953185 B 11020.00 
28956124 B 11031.00 
28956154 B 11026.00 
28957556 S 10971.00 
28982578 S 10985.00 
28983065 B 11022.00 
28983065 B 11024.00 
28990475 S 10986.00 
29013204 S 10985.00 
29013204 B 10987.50 
29015549 B 11024.00 
29019177 S 10979.00 
29019435 S 10971.00 
29024925 S 10973.00 
29026323 B 11015.00 
29029845 S 10974.00 
29029845 S 10973.00 
29045384 S 10977.00 
29045385 S 10976.00 
29049454 B 11019.00 
29049484 B 11017.00 
29060700 B 11026.00 
29062694 S 10979.50 
29062695 S 10977.00 
29063604 B 11032.00 
29065594 B 11037.00 
29066524 S 10980.00 
29066525 S 10977.00 
29067445 S 10980.00 
29067445 S 10977.00 
29067603 S 10988.00 
29067928 S 10996.00 
29067985 S 10996.50 
29069573 S 11002.50 
29091138 S 10983.00 
29109165 B 11031.00 
29116414 B 11030.00 
29117069 B 11022.00 
29117070 B 11030.00 
29226939 S 11012.50 
29256301 S 11013.50 
29278024 S 11012.50 
29281492 S 11014.50 
29293884 S 11012.50 
29308377 S 11015.50 
29309396 S 11012.50 
29309408 S 11015.50 
29314590 S 11012.50 
29318624 S 10999.00 
29323737 B 11028.50 
29324648 B 11030.00 
29328735 S 11002.00 
29328735 S 10999.00 
29337321 S 10983.00 
29337368 S 11003.00 
29338284 S 10994.00 
29338314 S 11003.00 
29341959 S 11017.00 
29343924 S 11003.00 
29343934 S 11013.00 
29346427 S 10999.00 
29350454 S 11003.00 
29350455 S 11000.00 
29351884 S 11003.50 
29351884 S 11000.00 
29353141 S 11010.50 
29354031 S 11000.00 
29354094 S 10990.00 
29354124 S 11000.00 
29354724 S 11003.50 
29354724 S 11000.00 
29354780 S 11010.50 
29356556 S 11000.00 
29357468 S 11010.50 
29358874 S 11007.00 
29358904 S 11010.50 
29366928 S 11000.00 
29367565 S 10990.00 
29367594 S 11000.00 
29369897 S 11011.50 
29371172 S 11000.00 
29373350 S 10984.00 
29373360 S 10999.00 
29384543 S 10984.00 
29384548 S 10998.00 
29388641 S 10984.00 
29388647 S 10992.00 
29392557 B 11029.00 
29394874 S 10982.00 
29394904 S 10991.00 
29399803 B 11030.00 
29402065 S 10995.50 
29402065 S 10992.00 
29410625 S 10996.50 
29410625 S 10992.00 
29411364 S 10982.00 
29411394 S 10992.00 
29416894 S 10982.00 
29416923 S 10991.00 
29437344 S 10982.00 
29437374 S 10990.00 
29437874 S 10982.00 
29437904 S 10984.50 
29454849 S 10976.00 
29454855 S 10985.50 
29455544 S 10986.00 
29463988 B 11024.00 
29465031 S 10995.00 
29469726 B 11023.67 
29471086 S 10992.00 
29471095 S 10996.00 
29473515 B 11022.67 
29473934 B 11023.67 
29477737 B 11029.67 
29492106 B 11027.67 
29497034 B 11026.67 
29499715 B 11019.50 
29504428 S 10992.00 
29504474 B 11019.67 
29504479 B 11027.67 
29504480 B 11019.67 
29504492 B 11027.67 
29504504 B 11026.67 
29504554 B 11027.67 
29508304 S 10992.50 
29523425 S 10992.00 
29536772 B 11018.67 
29539105 S 10993.00 
29541004 S 10992.00 
29541474 B 11015.00 
29548360 B 11016.00 
29553541 B 11013.20 
29556917 B 11021.47 
29557006 S 10997.50 
29567865 S 10998.50 
29572151 S 10997.50 
29610229 B 11025.47 
29610264 B 11026.47 
29624627 B 11029.67 
29640243 S 11002.50 
29641037 S 11004.50 
29663688 S 11004.00 
29666995 B 11028.67 
29667275 B 11029.67 
29677756 B 11029.74 
29711906 S 11001.00 
29719371 S 11007.00 
29730065 S 11009.50 
29733515 S 11007.00 
29733746 S 11010.00 
29733746 B 11028.67 
29733747 B 11029.74 
29733748 S 11007.00 
29733781 B 11028.67 
29733786 S 11010.00 
29734123 S 11007.00 
29734123 B 11029.74 
29734543 S 11008.00 
29760052 S 11002.00 
29760264 S 11008.00 
29792133 S 11017.50 
29798038 S 11008.00 
29798297 S 11015.00 
29800648 S 11019.50 
29822073 S 11016.00 
29839382 S 11016.50 
29839530 S 11012.00 
29847386 B 11028.67 
29864954 B 11027.67 
29874343 S 11016.50 
29964740 S 11012.50 
30015010 B 11025.00 
30023709 S 11012.00 
30024257 B 11027.67 
30027876 B 11025.00 
30045029 B 11027.67 
30062333 S 11012.50 
30074752 B 11028.67 
30074758 B 11024.67 
30077822 S 11012.00 
30086992 S 11013.50 
30088435 B 11028.67 
30088549 S 11012.00 
30154487 B 11026.17 
30156052 B 11028.67 
30244365 S 11012.50 
30246242 S 11009.50 
30246301 S 11014.50 
30311623 B 11029.74 
30327852 B 11030.40 
30349823 B 11032.35 
30359374 S 11025.00 
30365915 B 11034.75 
30378836 S 11014.50 
30383391 B 11032.50 
30384350 S 11025.00 
30385435 S 11026.00 
30385855 S 11025.00 
30386785 B 11034.75 
30386785 B 11037.00 
30386785 B 11040.00 
30386787 B 11037.00 
30387006 B 11040.00 
30387008 B 11037.00 
30387287 B 11040.00 
30391325 B 11063.00 
30392095 B 11060.50 
30392096 B 11062.00 
30395687 B 11050.00 
30399215 B 11048.50 
30409575 B 11052.00 
30409605 B 11050.00 
30411438 S 11030.00 
30412337 S 11025.00 
30414054 S 11035.00 
30419350 B 11062.00 
30419385 B 11053.00 
30420067 B 11062.00 
30420085 B 11066.00 
30420114 B 11063.00 
30422845 S 11029.00 
30426753 S 11025.00 
30428287 B 11056.50 
30431804 B 11052.00 
30433666 B 11050.50 
30441489 B 11052.00 
30444979 B 11050.50 
30450760 B 11052.00 
30451439 B 11050.50 
30465526 S 11042.50 
30467426 B 11052.00 
